<?xml version='1.0'?>
<robot name="wheelchair_model" xmlns:xacro="http://ros.org/wiki/xacro">

  <xacro:include filename="$(find wheelchair_description)/urdf/wheelchair.gazebo"/>
  <xacro:include filename="$(find wheelchair_description)/urdf/materials.xacro" />
  <xacro:include filename="$(find wheelchair_description)/urdf/macros.xacro" />

<!-- base -->
   <link name="base_footprint"/>
   <joint name="base_JOINT_1" type="fixed">
        <parent link="base_footprint"/>
        <child link="base" />
   </joint>

   <link name="base">
      <inertial>
        <origin xyz="0 0 0.693" rpy="0 1.5708 0"/>
         <mass value="10"/>
        <box_inertia m="10" x="0.42" y="0.53" z="0.05"/>
      </inertial>

      <visual>
        <origin xyz="0 0 0.693" rpy="0 0 0"/>
        <geometry>
          <box size="0.42 0.53 0.05"/>
        </geometry>
        <material name="white">
          <color rgba="1 1 1 1"/>
        </material>
      </visual>

      <collision>
        <origin xyz="0 0 0.693" rpy="0 0 0"/>
        <geometry>
          <box size="0.42 0.53 0.05"/>
        </geometry>
      </collision>
   </link>

<!-- pillar -->
   <joint name="base_JOINT_2" type="fixed">
      <parent link="base"/>
      <child link="pillar" />
      <origin xyz="0 0 0" rpy="0 0 0"/>
   </joint>

   <link name="pillar">
      <inertial>
        <origin xyz="-0.11 0 0.515" rpy="0 0 0"/>
         <mass value="2"/>
        <box_inertia m="2" x="0.2" y="0.2" z="0.3"/>
      </inertial>
     
      <visual>
        <origin xyz="-0.11 0 0.515" rpy="0 0 0"/>
        <geometry>
          <box size="0.20000 0.20000 0.3"/>
        </geometry>
        <material name="white">
          <color rgba="1 1 1 1"/>
        </material>
      </visual>

      <collision>
        <origin xyz="-0.11 0 0.515" rpy="0 0 0"/>
        <geometry>
          <box size="0.20000 0.20000 0.3"/>
        </geometry>
      </collision>
   </link>

<!-- prop -->
  <joint name="base_JOINT_3" type="fixed">
      <parent link="pillar"/>
      <child link="prop" />
      <origin xyz="-0.05 0 0.335" rpy="0 0 0"/>
  </joint>

   <link name="prop">
      <inertial>
        <origin xyz="0 0 0" rpy="0 0 0"/>
         <mass value="5"/>
        <box_inertia m="5" x="0.8" y="0.53" z="0.07"/>
      </inertial>
     
      <visual>
        <origin xyz="0.0 0 0" rpy="0 0 0"/>
        <geometry>
          <box size="0.8 0.53 0.070000"/>
        </geometry>
        <material name="white">
          <color rgba="1 1 1 1"/>
        </material>
      </visual>

      <collision>
        <origin xyz="0.0 0 0" rpy="0 0 0"/>
        <geometry>
          <box size="0.8 0.53 0.070000"/>
        </geometry>
      </collision>
   </link>

<!-- sensor_pillar -->
   <link name="sensor_pillar">
      <inertial>
        <origin xyz="0 0 0" rpy="0 0 0"/>
         <mass value="1"/>
        <box_inertia m="1" x="0.03" y="0.03" z="0.05"/>
      </inertial>
     
      <visual>
        <origin xyz="0 0 0" rpy="0 0 0"/>
        <geometry>
          <box size="0.03 0.03 0.5"/>
        </geometry>
        <material name="white">
          <color rgba="1 1 1 1"/>
        </material>
      </visual>

      <collision>
        <origin xyz="0 0 0" rpy="0 0 0"/>
        <geometry>
          <box size="0.03 0.03 0.5"/>
        </geometry>
      </collision>
   </link>

   <joint name="base_JOINT_4" type="fixed">
      <parent link="base"/>
      <child link="sensor_pillar" />
      <origin xyz="-0.16 -0.24 0.968" rpy="0 0 0"/>
   </joint>

<!-- caster_pillar 1 -->
   <joint name="base_JOINT_5" type="fixed">
      <parent link="base"/>
      <child link="caster_pillar1" />
      <origin xyz="-0.4 0.0 0.26" rpy="0 0 0"/>
   </joint>

   <link name="caster_pillar1">
      <inertial>
        <origin xyz="0 0 0" rpy="0 0 0"/>
         <mass value="1"/>
        <box_inertia m="1" x="0.05" y="0.05" z="0.08"/>
      </inertial>
     
      <visual>
        <origin xyz="0 0 0" rpy="0 0 0"/>
        <geometry>
          <box size="0.05 0.05 0.08"/>
        </geometry>
        <material name="white">
          <color rgba="1 1 1 1"/>
        </material>
      </visual>

      <collision>
        <origin xyz="0 0 0" rpy="0 0 0"/>
        <geometry>
          <box size="0.05 0.05 0.08"/>
        </geometry>
      </collision>
   </link>

<!-- caster_wheel 1 -->
  <joint name="casterwheel_JOINT1" type="fixed">
      <parent link="caster_pillar1"/>
      <child link="caster_wheel1" />
      <origin xyz="0.0 0.0 -0.15924" rpy="0 -1.570700 0"/>
  </joint>

  <link name="caster_wheel1">
      <inertial>
        <origin xyz="0 0 0" rpy="0 0 0"/>
         <mass value="5"/>
        <sphere_inertia m="5" r="0.1"/>
      </inertial>
     
      <visual>
        <origin xyz="0 0 0" rpy="-1.5707 0 0"/>
        <geometry>
          <sphere radius="0.10000"/>
        </geometry>
        <material name="black">
          <color rgba="0 0 0 1"/>
        </material>
      </visual>

      <collision>
        <origin xyz="0 0 0" rpy="0 0 0"/>
        <geometry>
          <sphere radius="0.10000"/>
        </geometry>
        <surface>
          <friction>
            <ode>
              <mu>0</mu>
              <mu2>0</mu2>
              <slip1>1.0</slip1>
              <slip2>1.0</slip2>
            </ode>
          </friction>
        </surface>
      </collision>
   </link>

<!-- caster_pillar 2 -->
   <joint name="base_JOINT_6" type="fixed">
      <parent link="base"/>
      <child link="caster_pillar2" />
      <origin xyz="0.3 0.0 0.26" rpy="0 0 0"/>
   </joint>

   <link name="caster_pillar2">
      <inertial>
        <origin xyz="0 0 0" rpy="0 0 0"/>
         <mass value="1"/>
        <box_inertia m="1" x="0.05" y="0.05" z="0.08"/>
      </inertial>
     
      <visual>
        <origin xyz="0 0 0" rpy="0 0 0"/>
        <geometry>
          <box size="0.05 0.05 0.08"/>
        </geometry>
        <material name="white">
          <color rgba="1 1 1 1"/>
        </material>
      </visual>

      <collision>
        <origin xyz="0 0 0" rpy="0 0 0"/>
        <geometry>
          <box size="0.05 0.05 0.08"/>
        </geometry>
      </collision>
   </link>

<!-- caster_wheel 2 -->
  <joint name="casterwheel_JOINT2" type="fixed">
      <parent link="caster_pillar2"/>
      <child link="caster_wheel2" />
      <origin xyz="0.0 0.0 -0.15924" rpy="0 -1.570700 0"/>
  </joint>

  <link name="caster_wheel2">
      <inertial>
        <origin xyz="0 0 0" rpy="0 0 0"/>
         <mass value="5"/>
        <sphere_inertia m="5" r="0.1"/>
      </inertial>
     
      <visual>
        <origin xyz="0 0 0" rpy="-1.5707 0 0"/>
        <geometry>
          <sphere radius="0.10000"/>
        </geometry>
        <material name="black">
          <color rgba="0 0 0 1"/>
        </material>
      </visual>

      <collision>
        <origin xyz="0 0 0" rpy="0 0 0"/>
        <geometry>
          <sphere radius="0.10000"/>
        </geometry>
        <surface>
          <friction>
            <ode>
              <mu>0</mu>
              <mu2>0</mu2>
              <slip1>1.0</slip1>
              <slip2>1.0</slip2>
            </ode>
          </friction>
        </surface>
      </collision>
   </link>

<!-- Represent joint for footrest -->
  <joint name="Footrest_JOINT_1" type="continuous">
     <parent link="base"/>
     <child link="footrest" />
     <origin xyz="0.235 0 0.693" rpy="1.5707 0 0"/>
     <axis xyz="0 0 -1"/>
     <limit effort="30" lower="-3.1416" upper="-1.5707" velocity="1"/>
  </joint>

  <link name="footrest">
    <inertial>
      <origin xyz="0 0 0" rpy="0 0 0"/>
      <mass value="1e-5"/>
        <inertia ixx="0.166667" ixy="0.0" ixz="0.0" iyy="0.166667" iyz="0.0" izz="0.166667"/>
    </inertial>

    <visual>
      <origin xyz="0 0 0" rpy="0 0 0"/>
      <geometry>
        <cylinder radius="0.025" length="0.53"/>
      </geometry>
      <material name="white">
        <color rgba="1 1 1 1"/>
      </material>
    </visual>

    <collision>
      <origin xyz="0 0 0" rpy="0 0 0"/>
      <geometry>
        <cylinder radius="0.025" length="0.53"/>
      </geometry>
    </collision>
  </link>

<!-- Represent link for footrest -->
   <joint name="Footrest_JOINT_2" type="fixed">
      <parent link="footrest"/>
      <child link="chair_footrest" />
        <origin xyz="0 0 0" rpy="0 0 1.8"/>
   </joint>

   <link name="chair_footrest">
      <inertial>
        <origin xyz="-0.175 0 0" rpy="0 0 0"/>
         <mass value="5"/>
        <box_inertia m="5" x="0.3" y="0.05" z="0.53"/>
      </inertial>
     
      <visual>
        <origin xyz="-0.175 0 0" rpy="0 0 0"/>
        <geometry>
          <box size="0.30000 0.050000 0.530000"/>
        </geometry>
        <material name="blue">
          <color rgba="0 0 0.8 1"/>
        </material>
      </visual>

      <collision>
        <origin xyz="-0.175 0 0" rpy="0 0 0"/>
        <geometry>
          <box size="0.30000 0.050000 0.530000"/>
        </geometry>
      </collision>
   </link>

<!-- Represent joint for seatback -->
   <joint name="Seatback_JOINT_1" type="continuous">
      <parent link="base"/>
      <child link="Seatback" />
      <origin xyz="-0.235 0 0.693" rpy="1.5707 0 0"/>
      <axis xyz="0 0 -1"/>
      <limit effort="30" lower="-3.1416" upper="-2.0943" velocity="1"/>
   </joint>

  <link name="Seatback">
    <inertial>
        <origin xyz="0 0 0" rpy="0 0 0"/>
      <mass value="1e-5"/>
        <inertia ixx="0.166667" ixy="0.0" ixz="0.0" iyy="0.166667" iyz="0.0" izz="0.166667"/>
    </inertial>

    <visual>
      <origin xyz="0 0 0" rpy="0 0 0"/>
      <geometry>
        <cylinder radius="0.025" length="0.53"/>
      </geometry>
      <material name="white">
        <color rgba="1 1 1 1"/>
      </material>
    </visual>

    <collision>
      <origin xyz="0 0 0" rpy="0 0 0"/>
      <geometry>
        <cylinder radius="0.025" length="0.53"/>
      </geometry>
    </collision>
  </link>

<!-- Represent link for seatback -->
   <joint name="Seatback_JOINT_2" type="fixed">
      <parent link="Seatback"/>
      <child link="chair_back" />
      <origin xyz="0 0 0" rpy="0 0 1.7"/>
   </joint>

   <link name="chair_back">
      <inertial>
        <origin xyz="0.415 0 0" rpy="0 0 0"/>
         <mass value="6"/>
        <box_inertia m="6" x="0.78" y="0.05" z="0.53"/>
      </inertial>

      <visual>
        <origin xyz="0.415 0 0" rpy="0 0 0"/>
        <geometry>
          <box size="0.78000 0.050000 0.530000"/>
        </geometry>
        <material name="red">
          <color rgba="0.8 0 0 1"/>
        </material>
      </visual>

      <collision>
        <origin xyz="0.415 0 0" rpy="0 0 0"/>
        <geometry>
          <box size="0.78000 0.050000 0.530000"/>
        </geometry>
      </collision>
   </link>

<!-- wheel_left -->
   <joint name="wheel_JOINT_left" type="continuous">
      <origin xyz="0.0 0.24 0.14000" rpy="-1.5707 0 0"/>
      <parent link="base"/>
      <child link="wheel_left"/>
      <axis xyz="0 0 1" rpy="0 0 0"/>
   </joint>

   <link name="wheel_left">
      <inertial>
        <origin xyz="0 0 0" rpy="0 0 0"/>
         <mass value="5"/>
        <cylinder_inertia m="5" r="0.14" h="0.05"/>
      </inertial>
     
      <visual>
        <origin xyz="0 0 0" rpy="-1.5707 0 0"/>
        <geometry>
          <mesh filename="package://wheelchair_description/meshes/left_tire.stl" scale="0.00422 0.00422 0.00422"/>
        </geometry>
        <material name="black">
          <color rgba="0 0 0 1"/>
        </material>
      </visual>

      <collision>
        <origin xyz="0 0 0" rpy="-1.5707 0 0"/>
        <geometry>
          <mesh filename="package://wheelchair_description/meshes/left_tire.stl" scale="0.00422 0.00422 0.00422"/>
        </geometry>
      </collision>
   </link>

<!-- wheel_right -->
   <joint name="wheel_JOINT_right" type="continuous">
      <origin xyz="0.0 -0.24 0.14000" rpy="-1.5707 0 0"/>
      <parent link="base"/>
      <child link="wheel_right"/>
      <axis xyz="0 0 1" rpy="0 0 0"/>
   </joint>

   <link name="wheel_right">
      <inertial>
        <origin xyz="0 0 0" rpy="0 0 0"/>
         <mass value="5"/>
        <cylinder_inertia m="5" r="0.14" h="0.05"/>
      </inertial>
     
      <visual>
        <origin xyz="0 0 0" rpy="-1.5707 0 0"/>
        <geometry>
          <mesh filename="package://wheelchair_description/meshes/right_tire.stl" scale="0.00422 0.00422 0.00422"/>
        </geometry>
        <material name="black">
          <color rgba="0 0 0 1"/>
        </material>
      </visual>

      <collision>
        <origin xyz="0 0 0" rpy="-1.5707 0 0"/>
        <geometry>
          <mesh filename="package://wheelchair_description/meshes/right_tire.stl" scale="0.00422 0.00422 0.00422"/>
        </geometry>
      </collision>
   </link>

<!-- armrest_right -->
   <joint name="armrest_right_Joint_1" type="fixed">
        <parent link="base"/>
        <child link="armrest_right_pillar_1" />
        <origin xyz="0 0 0" rpy="0 0 0"/>
   </joint>


   <link name="armrest_right_pillar_1">
      <inertial>
        <origin xyz="0.14 -0.24 0.768" rpy="0 0 0"/>
         <mass value="0.3"/>
        <inertia ixx="0.166667" ixy="0.0" ixz="0.0" iyy="0.166667" iyz="0.0" izz="0.166667"/>
      </inertial>
     
      <visual>
        <origin xyz="0.14 -0.24 0.768" rpy="0 0 0"/>
        <geometry>
          <box size="0.050000 0.050000 0.1"/>
        </geometry>
        <material name="white">
          <color rgba="1 1 1 1"/>
        </material>
      </visual>

      <collision>
        <origin xyz="0.14 -0.24 0.768" rpy="0 0 0"/>
        <geometry>
          <box size="0.050000 0.050000 0.1"/>
        </geometry>
      </collision>
   </link>

   <joint name="armrest_right_Joint_2" type="fixed">
        <parent link="base"/>
        <child link="armrest_right_pillar_2" />
        <origin xyz="0 0 0" rpy="0 0 0"/>
   </joint>

   <link name="armrest_right_pillar_2">
      <inertial>
        <origin xyz="-0.06 -0.24 0.768" rpy="0 0 0"/>
         <mass value="0.3"/>
        <inertia ixx="0.166667" ixy="0.0" ixz="0.0" iyy="0.166667" iyz="0.0" izz="0.166667"/>
      </inertial>
     
      <visual>
        <origin xyz="-0.06 -0.24 0.768" rpy="0 0 0"/>
        <geometry>
          <box size="0.050000 0.050000 0.1"/>
        </geometry>
        <material name="white">
          <color rgba="1 1 1 1"/>
        </material>
      </visual>

      <collision>
        <origin xyz="-0.06 -0.24 0.768" rpy="0 0 0"/>
        <geometry>
          <box size="0.050000 0.050000 0.1"/>
        </geometry>
      </collision>
   </link>

   <joint name="armrest_right_Joint_3" type="fixed">
        <parent link="armrest_right_pillar_1"/>
        <child link="armrest_right_top" />
        <origin xyz="0 0 0" rpy="0 0 0"/>
   </joint>

   <link name="armrest_right_top">
      <inertial>
        <origin xyz="0.04 -0.24 0.843" rpy="0 0 0"/>
         <mass value="0.3"/>
        <inertia ixx="0.166667" ixy="0.0" ixz="0.0" iyy="0.166667" iyz="0.0" izz="0.166667"/>
      </inertial>
     
      <visual>
        <origin xyz="0.04 -0.24 0.843" rpy="0 0 0"/>
        <geometry>
          <box size="0.3 0.05 0.050000"/>
        </geometry>
        <material name="white">
          <color rgba="1 1 1 1"/>
        </material>
      </visual>

      <collision>
        <origin xyz="0.04 -0.24 0.843" rpy="0 0 0"/>
        <geometry>
          <box size="0.3 0.05 0.050000"/>
        </geometry>
      </collision>
   </link>

   <joint name="armrest_left_Joint_1" type="fixed">
        <parent link="base"/>
        <child link="armrest_left_pillar_1" />
        <origin xyz="0 0 0" rpy="0 0 0"/>
   </joint>

   <link name="armrest_left_pillar_1">
      <inertial>
        <origin xyz="0.14 0.24 0.768" rpy="0 0 0"/>
         <mass value="0.3"/>
        <inertia ixx="0.166667" ixy="0.0" ixz="0.0" iyy="0.166667" iyz="0.0" izz="0.166667"/>
      </inertial>
     
      <visual>
        <origin xyz="0.14 0.24 0.768" rpy="0 0 0"/>
        <geometry>
          <box size="0.050000 0.050000 0.1"/>
        </geometry>
        <material name="white">
          <color rgba="1 1 1 1"/>
        </material>
      </visual>

      <collision>
        <origin xyz="0.14 0.240000 0.768" rpy="0 0 0"/>
        <geometry>
          <box size="0.050000 0.050000 0.1"/>
        </geometry>
      </collision>
   </link>

   <joint name="armrest_left_Joint_2" type="fixed">
        <parent link="base"/>
        <child link="armrest_left_pillar_2" />
        <origin xyz="0 0 0" rpy="0 0 0"/>
   </joint>

   <link name="armrest_left_pillar_2">
      <inertial>
        <origin xyz="-0.06 0.240000 0.768" rpy="0 0 0"/>
         <mass value="0.3"/>
        <inertia ixx="0.166667" ixy="0.0" ixz="0.0" iyy="0.166667" iyz="0.0" izz="0.166667"/>
      </inertial>
     
      <visual>
        <origin xyz="-0.06 0.240000 0.768" rpy="0 0 0"/>
        <geometry>
          <box size="0.050000 0.050000 0.1"/>
        </geometry>
        <material name="white">
          <color rgba="1 1 1 1"/>
        </material>
      </visual>

      <collision>
        <origin xyz="-0.06 0.240000 0.768" rpy="0 0 0"/>
        <geometry>
          <box size="0.050000 0.050000 0.1"/>
        </geometry>
      </collision>
   </link>

   <joint name="armrest_left_Joint_3" type="fixed">
        <parent link="armrest_left_pillar_1"/>
        <child link="armrest_left_top" />
        <origin xyz="0 0 0" rpy="0 0 0"/>
   </joint>

   <link name="armrest_left_top">
      <inertial>
        <origin xyz="0.04 0.240000 0.843" rpy="0 0 0"/>
         <mass value="0.3"/>
        <inertia ixx="0.166667" ixy="0.0" ixz="0.0" iyy="0.166667" iyz="0.0" izz="0.166667"/>
      </inertial>
     
      <visual>
        <origin xyz="0.04 0.240000 0.843" rpy="0 0 0"/>
        <geometry>
          <box size="0.3 0.05 0.050000"/>
        </geometry>
        <material name="white">
          <color rgba="1 1 1 1"/>
        </material>
      </visual>

      <collision>
        <origin xyz="0.04 0.240000 0.843" rpy="0 0 0"/>
        <geometry>
          <box size="0.3 0.05 0.050000"/>
        </geometry>
      </collision>
   </link>


   <link name="stick">
      <inertial>
        <origin xyz="0 0 0" rpy="0 0 0"/>
         <mass value="1e-5"/>
        <inertia ixx="0.005" ixy="0.0" ixz="0.0" iyy="0.005" iyz="0.0" izz="0.005"/>
      </inertial>
     
      <visual>
        <origin xyz="0 0 0" rpy="0 0 0"/>
        <geometry>
          <sphere radius="0.005"/>
        </geometry>
        <material name="black">
          <color rgba="0 0 0 1"/>
        </material>
      </visual>

      <collision>
        <origin xyz="0 0 0" rpy="0 0 0"/>
        <geometry>
          <sphere radius="0.005"/>
        </geometry>
      </collision>
   </link>

   <link name="stick_ball">
      <inertial>
        <origin xyz="0 0 0.0225" rpy="0 0 0"/>
         <mass value="1e-5"/>
        <inertia ixx="0.005" ixy="0.0" ixz="0.0" iyy="0.005" iyz="0.0" izz="0.005"/>
      </inertial>
     
      <visual>
        <origin xyz="0 0 0.0225" rpy="0 0 0"/>
        <geometry>
          <box size="0.010000 0.010000 0.035"/>
        </geometry>
        <material name="black">
          <color rgba="0 0 0 1"/>
        </material>
      </visual>

      <collision>
        <origin xyz="0 0 0.0225" rpy="0 0 0"/>
        <geometry>
          <box size="0.010000 0.010000 0.035"/>
        </geometry>
      </collision>
   </link>

   <joint name="Stick_JOINT" type="continuous">
        <parent link="armrest_right_top"/>
        <child link="stick" />
        <origin xyz="0.11 -0.24 0.873" rpy="0 0 0"/>
        <axis xyz="0 1 0"/>
   </joint>

   <joint name="stick_JOINT_1" type="fixed">
        <parent link="stick"/>
        <child link="stick_ball" />
        <origin xyz="0 0 0" rpy="0 0 0"/>
   </joint>

   <link name="front_button">
      <inertial>
        <origin xyz="0.11 0.24 0.873" rpy="0 0 0"/>
         <mass value="1e-5"/>
      <inertia ixx="1e-6" ixy="0" ixz="0" iyy="1e-6" iyz="0" izz="1e-6" />
      </inertial>
     
      <visual>
        <origin xyz="0.11 0.24 0.873" rpy="0 0 0"/>
        <geometry>
          <cylinder radius="0.020000" length="0.01"/>
        </geometry>
        <material name="blue">
          <color rgba="0 0 0.8 1"/>
        </material>
      </visual>

      <collision>
        <origin xyz="0.11 0.24 0.873" rpy="0 0 0"/>
        <geometry>
          <cylinder radius="0.020000" length="0.01"/>
        </geometry>
      </collision>
   </link>

   <joint name="button_JOINT_1" type="fixed">
      <parent link="armrest_left_top"/>
      <child link="front_button" />
      <origin xyz="0 0 0" rpy="0 0 0"/>
   </joint>

   <link name="back_button">
      <inertial>
        <origin xyz="0.06 0.24 0.873" rpy="0 0 0"/>
         <mass value="1e-5"/>
      <inertia ixx="1e-6" ixy="0" ixz="0" iyy="1e-6" iyz="0" izz="1e-6" />
      </inertial>
     
      <visual>
        <origin xyz="0.06 0.24 0.873" rpy="0 0 0"/>
        <geometry>
          <cylinder radius="0.020000" length="0.01"/>
        </geometry>
        <material name="red">
          <color rgba="0.8 0 0 1"/>
        </material>
      </visual>

      <collision>
        <origin xyz="0.06 0.24 0.873" rpy="0 0 0"/>
        <geometry>
          <cylinder radius="0.020000" length="0.01"/>
        </geometry>
      </collision>
   </link>

   <joint name="button_JOINT_2" type="fixed">
      <parent link="armrest_left_top"/>
      <child link="back_button" />
      <origin xyz="0 0 0" rpy="0 0 0"/>
   </joint>

<!-- IMU -->
  <link name="imu_link"/>

  <joint name="imu_joint" type="fixed">
    <parent link="base"/>
    <child link="imu_link"/>
    <origin xyz="0.0 0 0.068" rpy="0 0 0"/>
  </joint>

<!-- base_scan -->
   <joint name="sensor_joint" type="fixed">
      <parent link="base"/>
      <child link="base_scan" />
      <origin xyz="0.355 0 0.335" rpy="0 0 0"/>
   </joint>

  <link name="base_scan">
    <collision>
      <origin xyz="0 0 0" rpy="0 0 0" />
      <geometry>
        <box size="0.01 0.01 0.01" />
      </geometry>
    </collision>
    <visual>
      <origin xyz="0 0 0" rpy="0 0 0" />
      <geometry>
        <box size="0.01 0.01 0.01" />
      </geometry>
      <material name="red">
	<color rgba="1 0 0 1"/>
      </material>
    </visual>
    <inertial>
      <mass value="1e-5" />
      <origin xyz="0 0 0" rpy="0 0 0" />
      <inertia ixx="1e-6" ixy="0" ixz="0" iyy="1e-6" iyz="0" izz="1e-6" />
    </inertial>
  </link>

<!-- top_scan -->
  <joint name="sensor_joint_2" type="fixed">
     <parent link="base"/>
     <child link="top_scan" />
     <origin xyz="-0.13 -0.24 0.975" rpy="0 0 0"/>
  </joint>

  <link name="top_scan">
    <collision>
      <origin xyz="0 0 0" rpy="0 0 0" />
      <geometry>
        <box size="0.03 0.03 0.03" />
      </geometry>
    </collision>
    <visual>
      <origin xyz="0 0 0" rpy="0 0 0" />
      <geometry>
        <box size="0.03 0.03 0.03" />
      </geometry>
    </visual>
    <inertial>
      <mass value="1e-5" />
      <origin xyz="0 0 0" rpy="0 0 0" />
      <inertia ixx="1e-6" ixy="0" ixz="0" iyy="1e-6" iyz="0" izz="1e-6" />
    </inertial>
  </link>

  <!-- Camera -->
  <joint name="camera_joint" type="fixed">
    <axis xyz="0 1 0" />
    <origin xyz="-0.13 -0.24 1.005" rpy="0 0 -1.5707" />
    <parent link="base"/>
    <child link="camera_link"/>
  </joint>

  <link name="camera_link">
    <collision>
      <origin xyz="0 0 0" rpy="0 0 0"/>
      <geometry>
        <box size="0.03 0.03 0.03" />
      </geometry>
    </collision>

    <visual>
      <origin xyz="0 0 0" rpy="0 0 0"/>
      <geometry>
        <box size="0.03 0.03 0.03" />
      </geometry>
      <material name="red">
	<color rgba="1 0 0 1"/>
      </material>
    </visual>

    <inertial>
      <mass value="1e-5" />
      <origin xyz="0 0 0" rpy="0 0 0"/>
      <inertia ixx="1e-6" ixy="0" ixz="0" iyy="1e-6" iyz="0" izz="1e-6" />
    </inertial>
  </link>

<!-- transmission -->
  <xacro:macro name="transmission_block" params="joint_name idx">
      <transmission name="tran_${idx}">
        <type>transmission_interface/SimpleTransmission</type>
        <joint name="${joint_name}">
          <hardwareInterface>hardware_interface/EffortJointInterface</hardwareInterface>
        </joint>
        <actuator name="motor__${idx}">
          <hardwareInterface>hardware_interface/EffortJointInterface</hardwareInterface>
          <mechanicalReduction>1</mechanicalReduction>
        </actuator>
      </transmission>
  </xacro:macro>

  <xacro:transmission_block joint_name="Seatback_JOINT_1" idx="1"/>
  <xacro:transmission_block joint_name="Footrest_JOINT_1" idx="2"/>
  <xacro:transmission_block joint_name="Stick_JOINT" idx="3"/>
  <xacro:transmission_block joint_name="wheel_JOINT_left" idx="4"/>
  <xacro:transmission_block joint_name="wheel_JOINT_right" idx="5"/>

</robot>
